<?xml version="1.0" ?>
<!-- =================================================================================== -->
<!-- |    This document was autogenerated by xacro from box_chain.urdf.xacro           | -->
<!-- |    EDITING THIS FILE BY HAND IS NOT RECOMMENDED                                 | -->
<!-- =================================================================================== -->
<robot name="cardboard" xmlns:xacro="http://www.ros.org/wiki/xacro">
  <link name="base_link">
    <visual>
      <geometry>
        <box size="0 0 0"/>
      </geometry>
      <origin rpy="0 0 0" xyz="0 0 0"/>
    </visual>
  </link>
  <link name="human">
    <visual>
      <geometry>
        <box size="0 0 0"/>
      </geometry>
      <origin rpy="0 0 0" xyz="0 0 0"/>
    </visual>
  </link>
  <link name="box">
    <visual>
      <geometry>
        <box size="0.6 0.3 0.3"/>
      </geometry>
      <origin rpy="0 0 0" xyz="0.3 0 -0.15"/>
    </visual>
  </link>
  <link name="flap_1">
    <visual>
      <geometry>
        <box size="0.3 0.3 0.005"/>
      </geometry>
      <origin rpy="0 0 0" xyz="0.15 0 0"/>
      <material name="blue">
        <color rgba="0 0 .8 1"/>
      </material>
    </visual>
  </link>
  <link name="flap_2">
    <visual>
      <geometry>
        <box size="0.3 0.3 0.005"/>
      </geometry>
      <origin rpy="0 0 0" xyz="0.15 0 0"/>
      <material name="blue">
        <color rgba="0 0 .8 1"/>
      </material>
    </visual>
  </link>
  <joint name="joint_0" type="fixed">
    <origin rpy="0 0 0" xyz="0 0 0"/>
    <parent link="base_link"/>
    <child link="flap_1"/>
  </joint>
  <joint name="joint_1" type="revolute">
    <axis xyz="0 1 0"/>
    <limit effort="1000.0" lower="-3.14159265359" upper="1.57079632679" velocity="0.5"/>
    <origin rpy="0 0 0" xyz="0.3 0 0"/>
    <parent link="flap_1"/>
    <child link="box"/>
  </joint>
  <joint name="joint_2" type="revolute">
    <axis xyz="0 1 0"/>
    <limit effort="1000.0" lower="-3.14159265359" upper="1.57079632679" velocity="0.5"/>
    <origin rpy="0 0 0" xyz="0.6 0 0"/>
    <parent link="box"/>
    <child link="flap_2"/>
  </joint>
  <joint name="joint_3" type="fixed">
    <origin rpy="0 0 0" xyz="0.3 0 0"/>
    <parent link="flap_2"/>
    <child link="human"/>
  </joint>
</robot>

